promise.then(f1).catch(f2); //тут ошибка обработается
promise.then(f1, f2); //тут передается дальше